{
  "description": "Race condition in the FTPHandler class in ftpserver.py in pyftpdlib before 0.5.1 allows remote attackers to cause a denial of service (daemon outage) by establishing and then immediately closing a TCP connection, leading to the accept function having an unexpected return value of None, a different vulnerability than CVE-2010-3494.",
  "releases": {
    "bullseye": {
      "fixed_version": "0",
      "repositories": {
        "bullseye": "1.5.4-1"
      },
      "status": "resolved",
      "urgency": "unimportant"
    },
    "buster": {
      "fixed_version": "0",
      "repositories": {
        "buster": "1.5.4-1"
      },
      "status": "resolved",
      "urgency": "unimportant"
    },
    "jessie": {
      "fixed_version": "0",
      "repositories": {
        "jessie": "1.2.0-1"
      },
      "status": "resolved",
      "urgency": "unimportant"
    },
    "sid": {
      "fixed_version": "0",
      "repositories": {
        "sid": "1.5.4-1"
      },
      "status": "resolved",
      "urgency": "unimportant"
    },
    "stretch": {
      "fixed_version": "0",
      "repositories": {
        "stretch": "1.5.1-4"
      },
      "status": "resolved",
      "urgency": "unimportant"
    }
  },
  "scope": "remote"
}